<?xml version="1.0" ?>
<!-- =================================================================================== -->
<!-- |    This document was autogenerated by xacro from arthrobot.urdf.xacro           | -->
<!-- |    EDITING THIS FILE BY HAND IS NOT RECOMMENDED                                 | -->
<!-- =================================================================================== -->
<robot name="arthrobot">
  <ros2_control name="ArthrobotHardware" type="system">
    <!-- Custom Hardware Interface -->
    <hardware>
      <plugin>arthrobot_controller/ArthrobotHardwareInterface</plugin>
    </hardware>
    <!-- Arthrobot's Arm -->
    <joint name="waist_joint">
      <param name="initial_position">0.0</param>
      <command_interface name="position">
        <param name="min">waist_lower_limit</param>
        <param name="max">waist_upper_limit</param>
      </command_interface>
      <state_interface name="position"/>
    </joint>
    <joint name="shoulder_joint">
      <param name="initial_position">0.0</param>
      <command_interface name="position">
        <param name="min">shoulder_lower_limit</param>
        <param name="max">shoulder_upper_limit</param>
      </command_interface>
      <state_interface name="position"/>
    </joint>
    <joint name="forearm_joint">
      <param name="initial_position">0.0</param>
      <command_interface name="position">
        <param name="min">forearm_lower_limit</param>
        <param name="max">forearm_upper_limit</param>
      </command_interface>
      <state_interface name="position"/>
    </joint>
    <joint name="wrist_joint">
      <param name="initial_position">0.0</param>
      <command_interface name="position">
        <param name="min">wrist_lower_limit</param>
        <param name="max">wrist_upper_limit</param>
      </command_interface>
      <state_interface name="position"/>
    </joint>
    <joint name="palm_joint">
      <param name="initial_position">0.0</param>
      <command_interface name="position">
        <param name="min">palm_lower_limit</param>
        <param name="max">palm_upper_limit</param>
      </command_interface>
      <state_interface name="position"/>
    </joint>
    <!-- Arthrobot's Gripper -->
    <joint name="gripper_joint">
      <param name="initial_position">0.0</param>
      <command_interface name="position">
        <param name="min">gripper_lower_limit</param>
        <param name="max">gripper_upper_limit</param>
      </command_interface>
      <state_interface name="position"/>
    </joint>
  </ros2_control>
  <!-- Material Colors -->
  <material name="black">
    <color rgba="0.17 0.17 0.17 1.0"/>
  </material>
  <material name="gray">
    <color rgba="0.6 0.6 0.6 1.0"/>
  </material>
  <!-- This is the first link: empty link specifying the world -->
  <link name="world"/>
  <!--This is the joint that links the robot's base to the world frame -->
  <joint name="virtual_joint" type="fixed">
    <origin rpy="0.0 0.0 0.0" xyz="0.0 0.0 0.0"/>
    <parent link="world"/>
    <child link="base_link"/>
  </joint>
  <link name="base_link">
    <visual>
      <geometry>
        <mesh filename="package://arthrobot_description/meshes/base_link.stl" scale="0.001 0.001 0.001"/>
      </geometry>
      <origin rpy="0.0 0.0 -0.25" xyz="0.0 0.0 0.0"/>
      <material name="gray"/>
    </visual>
  </link>
  <joint name="waist_joint" type="revolute">
    <origin rpy="0.0 0.0 0.0" xyz="0.0 0.0 0.057"/>
    <parent link="base_link"/>
    <child link="waist_link"/>
    <axis xyz="0.0 0.0 1.0"/>
    <limit effort="2.0" lower="-1.7453" upper="1.7453" velocity="2.0"/>
  </joint>
  <link name="waist_link">
    <visual>
      <geometry>
        <mesh filename="package://arthrobot_description/meshes/waist_link.stl" scale="0.001 0.001 0.001"/>
      </geometry>
      <origin rpy="0.0 0.0 0.0" xyz="0.0 0.0 0.0"/>
      <material name="gray"/>
    </visual>
  </link>
  <joint name="shoulder_joint" type="revolute">
    <origin rpy="1.45 0.0 0.0" xyz="0.0 0.014 0.071"/>
    <parent link="waist_link"/>
    <child link="shoulder_link"/>
    <axis xyz="1.0 0.0 0.0"/>
    <limit effort="2.0" lower="-1.693" upper="1.7453" velocity="2.0"/>
  </joint>
  <link name="shoulder_link">
    <visual>
      <geometry>
        <mesh filename="package://arthrobot_description/meshes/shoulder_link.stl" scale="0.001 0.001 0.001"/>
      </geometry>
      <origin rpy="0.0 0.0 0.0" xyz="0.0 0.0 0.0"/>
      <material name="gray"/>
    </visual>
  </link>
  <joint name="forearm_joint" type="revolute">
    <origin rpy="0.0 0.0 0.0" xyz="0.0 0.117 0.0029"/>
    <parent link="shoulder_link"/>
    <child link="forearm_link"/>
    <axis xyz="1.0 0.0 0.0"/>
    <limit effort="2.0" lower="-1.7453" upper="1.7453" velocity="2.0"/>
  </joint>
  <link name="forearm_link">
    <visual>
      <geometry>
        <mesh filename="package://arthrobot_description/meshes/forearm_link.stl" scale="0.001 0.001 0.001"/>
      </geometry>
      <origin rpy="0.0 0.0 0.0" xyz="0.0 0.0 0.0"/>
      <material name="gray"/>
    </visual>
  </link>
  <joint name="wrist_joint" type="revolute">
    <origin rpy="0.0 0.0 0.0" xyz="-0.0113 0.0928 0.0023"/>
    <parent link="forearm_link"/>
    <child link="wrist_link"/>
    <axis xyz="0.0 1.0 0.0"/>
    <limit effort="2.0" lower="-1.7453" upper="1.7453" velocity="2.0"/>
  </joint>
  <link name="wrist_link">
    <visual>
      <geometry>
        <mesh filename="package://arthrobot_description/meshes/wrist_link.stl" scale="0.001 0.001 0.001"/>
      </geometry>
      <origin rpy="0.0 0.0 0.0" xyz="0.0 0.0 0.0"/>
      <material name="gray"/>
    </visual>
  </link>
  <joint name="palm_joint" type="revolute">
    <origin rpy="0.0 0.0 0.0" xyz="0.0142 0.033 0.0012"/>
    <parent link="wrist_link"/>
    <child link="palm_link"/>
    <axis xyz="1.0 0.0 0.0"/>
    <limit effort="2.0" lower="-1.570796326795" upper="1.570796326795" velocity="2.0"/>
  </joint>
  <link name="palm_link">
    <visual>
      <geometry>
        <mesh filename="package://arthrobot_description/meshes/palm_link.stl" scale="0.001 0.001 0.001"/>
      </geometry>
      <origin rpy="0.0 0.0 0.0" xyz="0.0 0.0 0.0"/>
      <material name="gray"/>
    </visual>
  </link>
  <!-- Extra joint for the interactive marker -->
  <joint name="gripper_support_joint" type="fixed">
    <origin rpy="0.0 0.0 0.0" xyz="0.0 0.1 0.0"/>
    <parent link="palm_link"/>
    <child link="gripper_support"/>
  </joint>
  <link name="gripper_support">
    <visual>
      <!-- small visual to mark the new link -->
      <origin rpy="0 0 0" xyz="0 0 0"/>
      <geometry>
        <box size="0.005 0.005 0.005"/>
      </geometry>
    </visual>
  </link>
  <joint name="gripper_joint" type="revolute">
    <origin rpy="0.0 0.0 0.0" xyz="0.003 0.0385 0.0035"/>
    <parent link="palm_link"/>
    <child link="right_finger_base_link"/>
    <axis xyz="0.0 0.0 -1.0"/>
    <limit effort="2.0" lower="0.0" upper="1.7453" velocity="2.0"/>
  </joint>
  <link name="right_finger_base_link">
    <visual>
      <geometry>
        <mesh filename="package://arthrobot_description/meshes/right_finger_base_link.stl" scale="0.001 0.001 0.001"/>
      </geometry>
      <origin rpy="0.0 0.0 0.0" xyz="0.0 0.0 0.0"/>
      <material name="gray"/>
    </visual>
  </link>
  <joint name="palm_left_finger_base_joint" type="revolute">
    <origin rpy="0.0 0.0 0.0" xyz="-0.017 0.0385 0.0035"/>
    <parent link="palm_link"/>
    <child link="left_finger_base_link"/>
    <axis xyz="0.0 0.0 -1.0"/>
    <limit effort="2.0" lower="0.0" upper="1.5708" velocity="2.0"/>
    <mimic joint="gripper_joint" multiplier="-1" offset="0"/>
  </joint>
  <link name="left_finger_base_link">
    <visual>
      <geometry>
        <mesh filename="package://arthrobot_description/meshes/left_finger_base_link.stl" scale="0.001 0.001 0.001"/>
      </geometry>
      <origin rpy="0.0 0.0 0.0" xyz="0.0 0.0 0.0"/>
      <material name="gray"/>
    </visual>
  </link>
  <joint name="right_finger_joint" type="revolute">
    <origin rpy="0.0 0.0 0.0" xyz="-0.0001 0.0587 0.01"/>
    <parent link="palm_link"/>
    <child link="right_finger_link"/>
    <axis xyz="0.0 0.0 -1.0"/>
    <limit effort="2.0" lower="0.0" upper="1.5708" velocity="2.0"/>
    <mimic joint="gripper_joint" multiplier="1.2" offset="0"/>
  </joint>
  <link name="right_finger_link">
    <visual>
      <geometry>
        <mesh filename="package://arthrobot_description/meshes/right_finger_link.stl" scale="0.001 0.001 0.001"/>
      </geometry>
      <origin rpy="0.0 0.0 0.0" xyz="0.0 0.0 0.0"/>
      <material name="gray"/>
    </visual>
  </link>
  <joint name="left_finger_joint" type="revolute">
    <origin rpy="0.0 0.0 0.0" xyz="-0.014 0.0587 0.01"/>
    <parent link="palm_link"/>
    <child link="left_finger_link"/>
    <axis xyz="0.0 0.0 -1.0"/>
    <limit effort="2.0" lower="0.0" upper="1.5708" velocity="2.0"/>
    <mimic joint="palm_left_finger_base_joint" multiplier="1.2" offset="0"/>
  </joint>
  <link name="left_finger_link">
    <visual>
      <geometry>
        <mesh filename="package://arthrobot_description/meshes/left_finger_link.stl" scale="0.001 0.001 0.001"/>
      </geometry>
      <origin rpy="0.0 0.0 0.0" xyz="0.0 0.0 0.0"/>
      <material name="gray"/>
    </visual>
  </link>
  <joint name="left_fingertip_joint" type="revolute">
    <origin rpy="0.0 0.0 0.0" xyz="-0.007 0.035 0.008"/>
    <parent link="left_finger_base_link"/>
    <child link="left_fingertip_link"/>
    <axis xyz="0.0 0.0 -1.0"/>
    <limit effort="2.0" lower="0.0" upper="1.5708" velocity="2.0"/>
    <mimic joint="gripper_joint" multiplier="1" offset="0"/>
  </joint>
  <link name="left_fingertip_link">
    <visual>
      <geometry>
        <mesh filename="package://arthrobot_description/meshes/left_fingertip_link.stl" scale="0.001 0.001 0.001"/>
      </geometry>
      <origin rpy="0.0 0.0 0.0" xyz="0.0 0.0 0.0"/>
      <material name="gray"/>
    </visual>
  </link>
  <joint name="right_fingertip_joint" type="revolute">
    <origin rpy="0.0 0.0 0.0" xyz="0.01 0.035 0.008"/>
    <parent link="right_finger_base_link"/>
    <child link="right_fingertip_link"/>
    <axis xyz="0.0 0.0 -1.0"/>
    <limit effort="2.0" lower="0.0" upper="1.5708" velocity="2.0"/>
    <mimic joint="gripper_joint" multiplier="-1" offset="0"/>
  </joint>
  <link name="right_fingertip_link">
    <visual>
      <geometry>
        <mesh filename="package://arthrobot_description/meshes/right_fingertip_link.stl" scale="0.001 0.001 0.001"/>
      </geometry>
      <origin rpy="0.0 0.0 0.0" xyz="0.0 0.0 0.0"/>
      <material name="gray"/>
    </visual>
  </link>
</robot>
