<?xml version="1.0" ?>
<!-- =================================================================================== -->
<!-- |    This document was autogenerated by xacro from arthrobot.urdf.xacro           | -->
<!-- |    EDITING THIS FILE BY HAND IS NOT RECOMMENDED                                 | -->
<!-- =================================================================================== -->
<robot name="arthrobot">
  <!-- Gazebo ros2_control plugin -->
  <gazebo>
    <plugin filename="libgazebo_ros2_control.so" name="gazebo_ros2_control">
      <robot_param>robot_description</robot_param>
      <robot_param_node>robot_state_publisher</robot_param_node>
      <parameters>/home/fadi/ArthroBot/arthrobot_ws/install/arthrobot_controller/share/arthrobot_controller/config/arthrobot_controllers.yaml</parameters>
    </plugin>
  </gazebo>
  <ros2_control name="RobotSystem" type="system">
    <!-- ros2_control Gazebo -->
    <hardware>
      <plugin>gazebo_ros2_control/GazeboSystem</plugin>
    </hardware>
    <joint name="joint_1">
      <command_interface name="position">
        <param name="min">-3.14159265359</param>
        <param name="max">3.14159265359</param>
      </command_interface>
      <state_interface name="position"/>
    </joint>
    <joint name="joint_2">
      <command_interface name="position">
        <param name="min">-3.14159265359</param>
        <param name="max">3.14159265359</param>
      </command_interface>
      <state_interface name="position"/>
    </joint>
    <joint name="joint_3">
      <command_interface name="position">
        <param name="min">-3.14159265359</param>
        <param name="max">3.14159265359</param>
      </command_interface>
      <state_interface name="position"/>
    </joint>
    <joint name="joint_4">
      <command_interface name="position">
        <param name="min">-3.14159265359</param>
        <param name="max">3.14159265359</param>
      </command_interface>
      <state_interface name="position"/>
    </joint>
    <joint name="joint_5">
      <command_interface name="position">
        <param name="min">-3.14159265359</param>
        <param name="max">3.14159265359</param>
      </command_interface>
      <state_interface name="position"/>
    </joint>
  </ros2_control>
  <!-- This is the first link: empty link specifying the world -->
  <link name="world"/>
  <!--This is the joint that links the robot's base to the world frame -->
  <joint name="world_base_joint" type="fixed">
    <origin rpy="0.0 0.0 0.0" xyz="0.0 0.0 0.0"/>
    <parent link="world"/>
    <child link="base_link"/>
  </joint>
  <!-- The base link (wooden frame and the metalic support)-->
  <link name="base_link">
    <inertial>
      <origin rpy="0 0 0" xyz="0 0 0"/>
      <mass value="2.0"/>
      <inertia ixx="1.0" ixy="0.0" ixz="0.0" iyy="1.0" iyz="0.0" izz="1.0"/>
    </inertial>
    <visual>
      <origin rpy="0.0 0.0 0.0" xyz="0.0 0.0 0.0225"/>
      <geometry>
        <box size="0.19 0.16 0.045"/>
      </geometry>
    </visual>
    <collision>
      <origin rpy="0.0 0.0 0.0" xyz="0.0 0.0 0.00225"/>
      <geometry>
        <box size="0.19 0.16 0.045"/>
      </geometry>
    </collision>
    <visual>
      <origin rpy="0.0 0.0 0.0" xyz="-0.007 0.0085 0.063"/>
      <geometry>
        <box size="0.07 0.06 0.036"/>
      </geometry>
    </visual>
    <collision>
      <origin rpy="0.0 0.0 0.0" xyz="-0.007 0.0085 0.063"/>
      <geometry>
        <box size="0.07 0.06 0.036"/>
      </geometry>
    </collision>
  </link>
  <!-- Joint that attaches the base with motor 1-->
  <joint name="base_motor_link" type="fixed">
    <origin rpy="0.0 0.0 0.0" xyz="-0.007 0.0085 0.081"/>
    <parent link="base_link"/>
    <child link="motor1_link"/>
  </joint>
  <!--Motor 1 link-->
  <link name="motor1_link">
    <inertial>
      <origin rpy="0 0 0" xyz="0 0 0"/>
      <mass value="0.3"/>
      <inertia ixx="1.0" ixy="0.0" ixz="0.0" iyy="1.0" iyz="0.0" izz="1.0"/>
    </inertial>
    <visual>
      <origin rpy="0.0 0.0 0.0" xyz="0.0 0.0 0.005"/>
      <geometry>
        <box size="0.04 0.022 0.01"/>
      </geometry>
    </visual>
    <collision>
      <origin rpy="0.0 0.0 0.0" xyz="0.0 0.0 0.005"/>
      <geometry>
        <box size="0.04 0.022 0.01"/>
      </geometry>
    </collision>
    <visual>
      <origin rpy="0.0 0.0 0.0" xyz="-0.01 0.0 0.014"/>
      <geometry>
        <cylinder length="0.008" radius="0.006"/>
      </geometry>
    </visual>
    <collision>
      <origin rpy="0.0 0.0 0.0" xyz="-0.01 0.0 0.004"/>
      <geometry>
        <cylinder length="0.008" radius="0.006"/>
      </geometry>
    </collision>
  </link>
  <!--Joint between motor 1 and motor 2-->
  <joint name="joint_1" type="revolute">
    <origin rpy="0.0 0.0 0.0" xyz="-0.01 0.0 0.018"/>
    <parent link="motor1_link"/>
    <child link="motor2_link"/>
    <axis xyz="0.0 0.0 1.0"/>
    <limit effort="80" lower="-3.1415" upper="3.1415" velocity="50"/>
  </joint>
  <!--Motor 2 link-->
  <link name="motor2_link">
    <inertial>
      <origin rpy="0 0 0" xyz="0 0 0"/>
      <mass value="0.2"/>
      <inertia ixx="1.0" ixy="0.0" ixz="0.0" iyy="1.0" iyz="0.0" izz="1.0"/>
    </inertial>
    <visual>
      <origin rpy="0.0 0.0 0.0" xyz="0.0 0.01 0.0125"/>
      <geometry>
        <box size="0.057 0.06 0.025"/>
      </geometry>
    </visual>
    <collision>
      <origin rpy="0.0 0.0 0.0" xyz="0.0 0.01 0.0125"/>
      <geometry>
        <box size="0.057 0.06 0.025"/>
      </geometry>
    </collision>
  </link>
  <!--Joint between motor 2 and bar 1-->
  <joint name="joint_2" type="revolute">
    <origin rpy="0.0 0.0 0.0" xyz="-0.0285 0.02 0.0125"/>
    <parent link="motor2_link"/>
    <child link="bar1_link"/>
    <axis xyz="-1.0 0.0 0.0"/>
    <limit effort="80" lower="-3.1415" upper="3.1415" velocity="50"/>
  </joint>
  <!--bar 1 link-->
  <link name="bar1_link">
    <inertial>
      <origin rpy="0 0 0" xyz="0 0 0"/>
      <mass value="0.1"/>
      <inertia ixx="1.0" ixy="0.0" ixz="0.0" iyy="1.0" iyz="0.0" izz="1.0"/>
    </inertial>
    <visual>
      <origin rpy="0.0 0.0 0.0" xyz="-0.001 0.0 0.0525"/>
      <geometry>
        <box size="0.002 0.025 0.105"/>
      </geometry>
    </visual>
    <collision>
      <origin rpy="0.0 0.0 0.0" xyz="-0.001 0.0 0.0525"/>
      <geometry>
        <box size="0.002 0.025 0.105"/>
      </geometry>
    </collision>
    <visual>
      <origin rpy="0.0 0.0 0.0" xyz="0.058 0.0 0.0525"/>
      <geometry>
        <box size="0.002 0.025 0.105"/>
      </geometry>
    </visual>
    <collision>
      <origin rpy="0.0 0.0 0.0" xyz="-0.001 0.0 0.0525"/>
      <geometry>
        <box size="0.002 0.025 0.105"/>
      </geometry>
    </collision>
  </link>
  <!--joint between bar 1 and bar 2-->
  <joint name="joint_3" type="revolute">
    <origin rpy="0.0 0.0 0.0" xyz="-0.002 0.0 0.105"/>
    <parent link="bar1_link"/>
    <child link="bar2_link"/>
    <axis xyz="-1.0 0.0 0.0"/>
    <limit effort="80" lower="-3.1415" upper="3.1415" velocity="50"/>
  </joint>
  <!--bar 2 link-->
  <link name="bar2_link">
    <inertial>
      <origin rpy="0 0 0" xyz="0 0 0"/>
      <mass value="0.1"/>
      <inertia ixx="1.0" ixy="0.0" ixz="0.0" iyy="1.0" iyz="0.0" izz="1.0"/>
    </inertial>
    <visual>
      <origin rpy="0.0 0.0 0.0" xyz="-0.001 0.0 0.049"/>
      <geometry>
        <box size="0.002 0.025 0.098"/>
      </geometry>
    </visual>
    <collision>
      <origin rpy="0.0 0.0 0.0" xyz="-0.001 0.0 0.049"/>
      <geometry>
        <box size="0.002 0.025 0.098"/>
      </geometry>
    </collision>
    <visual>
      <origin rpy="0.0 0.0 0.0" xyz="0.062 0.0 0.049"/>
      <geometry>
        <box size="0.002 0.025 0.098"/>
      </geometry>
    </visual>
    <collision>
      <origin rpy="0.0 0.0 0.0" xyz="0.062 0.0 0.049"/>
      <geometry>
        <box size="0.002 0.025 0.098"/>
      </geometry>
    </collision>
  </link>
  <!--joint bar 2 motor 3-->
  <joint name="joint_4" type="revolute">
    <origin rpy="0.0 0.0 0.0" xyz="0.002 0.0 0.098"/>
    <parent link="bar2_link"/>
    <child link="motor3_link"/>
    <axis xyz="-1.0 0.0 0.0"/>
    <limit effort="80" lower="-3.1415" upper="3.1415" velocity="50"/>
  </joint>
  <!--motor 3 link-->
  <link name="motor3_link">
    <inertial>
      <origin rpy="0 0 0" xyz="0 0 0"/>
      <mass value="0.1"/>
      <inertia ixx="1.0" ixy="0.0" ixz="0.0" iyy="1.0" iyz="0.0" izz="1.0"/>
    </inertial>
    <visual>
      <origin rpy="0.0 0.0 0.0" xyz="0.0285 0.01 0.0"/>
      <geometry>
        <box size="0.056 0.06 0.025"/>
      </geometry>
    </visual>
    <collision>
      <origin rpy="0.0 0.0 0.0" xyz="0.0285 0.01 0.0"/>
      <geometry>
        <box size="0.056 0.06 0.025"/>
      </geometry>
    </collision>
  </link>
  <!--motor 3 motor 4 joint-->
  <joint name="motor3_motor4_joint" type="fixed">
    <origin rpy="0.0 0.0 0.0" xyz="0.0285 0.02 0.0125"/>
    <parent link="motor3_link"/>
    <child link="motor4_link"/>
  </joint>
  <!-- motor 4 link-->
  <link name="motor4_link">
    <inertial>
      <origin rpy="0 0 0" xyz="0 0 0"/>
      <mass value="0.1"/>
      <inertia ixx="1.0" ixy="0.0" ixz="0.0" iyy="1.0" iyz="0.0" izz="1.0"/>
    </inertial>
    <visual>
      <origin rpy="0.0 0.0 0.0" xyz="0.0 0.0 0.023"/>
      <geometry>
        <box size="0.042 0.022 0.046"/>
      </geometry>
    </visual>
    <collision>
      <origin rpy="0.0 0.0 0.0" xyz="0.0 0.0 0.023"/>
      <geometry>
        <box size="0.042 0.022 0.046"/>
      </geometry>
    </collision>
  </link>
  <!--Joint motor 4 ee link-->
  <joint name="joint_5" type="revolute">
    <origin rpy="0.0 0.0 0.0" xyz="-0.01 0.0 0.046"/>
    <parent link="motor4_link"/>
    <child link="ee_link"/>
    <axis xyz="0.0 0.0 1.0"/>
    <limit effort="80" lower="-3.1415" upper="3.1415" velocity="50"/>
  </joint>
  <!-- ee link (end effector)-->
  <link name="ee_link">
    <inertial>
      <origin rpy="0 0 0" xyz="0 0 0"/>
      <mass value="0.05"/>
      <inertia ixx="1.0" ixy="0.0" ixz="0.0" iyy="1.0" iyz="0.0" izz="1.0"/>
    </inertial>
    <visual>
      <origin rpy="-1.57 0.0 0.0" xyz="0.0 0.0 0.012"/>
      <geometry>
        <cylinder length="0.145" radius="0.012"/>
      </geometry>
    </visual>
    <collision>
      <origin rpy="-1.57 0.0 0.0" xyz="0.0 0.0 0.012"/>
      <geometry>
        <cylinder length="0.145" radius="0.012"/>
      </geometry>
    </collision>
  </link>
  <transmission name="transmission_1">
    <plugin>transmission_interface/SimpleTransmission</plugin>
    <actuator name="motor_1" role="actuator1"/>
    <joint name="joint_1" role="joint1">
      <mechanical_reduction>1.0</mechanical_reduction>
    </joint>
  </transmission>
  <transmission name="transmission_2">
    <plugin>transmission_interface/SimpleTransmission</plugin>
    <actuator name="motor_2" role="actuator1"/>
    <joint name="joint_2" role="joint1">
      <mechanical_reduction>1.0</mechanical_reduction>
    </joint>
  </transmission>
  <transmission name="transmission_3">
    <plugin>transmission_interface/SimpleTransmission</plugin>
    <actuator name="motor_3" role="actuator1"/>
    <joint name="joint_3" role="joint1">
      <mechanical_reduction>1.0</mechanical_reduction>
    </joint>
  </transmission>
  <transmission name="transmission_4">
    <plugin>transmission_interface/SimpleTransmission</plugin>
    <actuator name="motor_4" role="actuator1"/>
    <joint name="joint_4" role="joint1">
      <mechanical_reduction>1.0</mechanical_reduction>
    </joint>
  </transmission>
  <transmission name="transmission_5">
    <plugin>transmission_interface/SimpleTransmission</plugin>
    <actuator name="motor_5" role="actuator1"/>
    <joint name="joint_5" role="joint1">
      <mechanical_reduction>1.0</mechanical_reduction>
    </joint>
  </transmission>
</robot>
